Workbook

Sheet Question
A1: Review | B1: Class | E1: SOLUTION | H1: Review | I1: Class
A2: This book is perfect! I'm a first time new mom, and this book made it so easy to keep track of feedings, diaper changes, sleep. Definitely would recommend this for new moms. Plus it's small enough that I throw in the diaper back for doctor visits. | B2: 1 | H2: This book is perfect! I'm a first time new mom, and this book made it so easy to keep track of feedings, diaper changes, sleep. Definitely would recommend this for new moms. Plus it's small enough that I throw in the diaper back for doctor visits. | I2: 1
A3: I use this so that our babysitter (grandma) can keep track of what goes on during the day. We've recorded so many milestones since we received this. I'll definitely get another one in 6 months when we finish this book. | B3: 1 | H3: I use this so that our babysitter (grandma) can keep track of what goes on during the day. We've recorded so many milestones since we received this. I'll definitely get another one in 6 months when we finish this book. | I3: 1
A4: I have used this book since my son was born. It's a great and handy way to keep track of when and how much eats and when I change his diaper. Makes it easy to discuss his progress with his doctor. This journal is great for his grandparents who watch him while I'm gone. Highly recommend this journal for all parents of children especially for those with little ones under a year of age. | B4: 1 | H4: I have used this book since my son was born. It's a great and handy way to keep track of when and how much eats and when I change his diaper. Makes it easy to discuss his progress with his doctor. This journal is great for his grandparents who watch him while I'm gone. Highly recommend this journal for all parents of children especially for those with little ones under a year of age. | I4: 1
A5: My friend recommended this teether because her daughter loves it. However, my daughter loves throwing it on the floor. Hopefully, it will work better for you. | B5: 0 | H5: My friend recommended this teether because her daughter loves it. However, my daughter loves throwing it on the floor. Hopefully, it will work better for you. | I5: 0
A6: Don't waste your money, my son would rather suck on his fingers than to use this messaging corn teether. The massager really has to be squeezed in order to work. | B6: 0 | H6: Don't waste your money, my son would rather suck on his fingers than to use this messaging corn teether. The massager really has to be squeezed in order to work. | I6: 0
A7: This is the best way to keep track of when your baby eats, sleeps, poops, gets a bath, etc. It's also a great way to keep track of which side baby nursed on. I took this to all infant doc appt. And it's a great gift! | B7: 1 | H7: This is the best way to keep track of when your baby eats, sleeps, poops, gets a bath, etc. It's also a great way to keep track of which side baby nursed on. I took this to all infant doc appt. And it's a great gift! | I7: 1
A8: Inside is not nice and clean. All in all, it does not what is advertised and keeps us sane on what was done/changed when. | B8: 0 | H8: Inside is not nice and clean. All in all, it does not what is advertised and keeps us sane on what was done/changed when. | I8: 0
A9: We bought these trucks for our 15 month. old daughter and 4 mo. old son- We love them! They are nesting which is fun for our daughter to look underneath the trucks to find the next one or they can stack one on top of the other to make a tower. Perfect first trucks! And they aren't too big- a perfect size! | B9: 1 | H9: We bought these trucks for our 15 month. old daughter and 4 mo. old son- We love them! They are nesting which is fun for our daughter to look underneath the trucks to find the next one or they can stack one on top of the other to make a tower. Perfect first trucks! And they aren't too big- a perfect size! | I9: 1
A10: My son's therapist brings this toy over and he just loves it. He loves to move the ladder on the fire truck up and down. This is one of his favorite toys and he doesn't play with a lot of baby and toddler toys (gets bored easy). | B10: ? | H10: My son's therapist brings this toy over and he just loves it. He loves to move the ladder on the fire truck up and down. This is one of his favorite toys and he doesn't play with a lot of baby and toddler toys (gets bored easy). | I10: 0
A11: The layout of the hours are a little tricky. The print on each page is a light grey, so trying to journal diapers, bottles, meds in the middle of the night is a challenge. I could not use the space to make more notes and comment on something cute that day. | B11: ? | H11: The layout of the hours are a little tricky. The print on each page is a light grey, so trying to journal diapers, bottles, meds in the middle of the night is a challenge. I could not use the space to make more notes and comment on something cute that day. | I11: 1

Sheet TEXT PREPROCESSING
A1: STEP-1 :Tokenization
A2: DOC N0 | B2: DOCUMENT | BX2: Class
A3: D1 | B3: This | C3: book | D3: is | E3: perfect! | F3: I'm | G3: a | H3: first | I3: time | J3: new | K3: mom, | L3: and | M3: this | N3: book | O3: made | P3: it | Q3: so | R3: easy | S3: to | T3: keep | U3: track | V3: of | W3: feedings, | X3: diaper | Y3: changes, | Z3: sleep. | AA3: Definitely | AB3: would | AC3: recommend | AD3: this | AE3: for | AF3: new | AG3: moms. | AH3: Plus | AI3: it's | AJ3: small | AK3: enough | AL3: that | AM3: I | AN3: throw | AO3: in | AP3: the | AQ3: diaper | AR3: back | AS3: for | AT3: doctor | AU3: visits. | BX3: 1
A4: D2 | B4: I | C4: use | D4: this | E4: so | F4: that | G4: our | H4: babysitter | I4: (grandma) | J4: can | K4: keep | L4: track | M4: of | N4: what | O4: goes | P4: on | Q4: during | R4: the | S4: to | T4: We've | U4: recorded | V4: so | W4: many | X4: milestones | Y4: since | Z4: we | AA4: received | AB4: this. | AC4: I'll | AD4: definitely | AE4: get | AF4: another | AG4: one | AH4: in | AI4: 6 | AJ4: months | AK4: when | AL4: we | AM4: finish | AN4: this | AO4: book. | BX4: 1
A5: D3 | B5: I | C5: have | D5: used | E5: this | F5: book | G5: since | H5: my | I5: son | J5: was | K5: born. | L5: It's | M5: a | N5: great | O5: and | P5: handy | Q5: way | R5: to | S5: to | T5: track | U5: of | V5: when | W5: and | X5: how | Y5: much | Z5: eats | AA5: and | AB5: when | AC5: I | AD5: change | AE5: his | AF5: diaper. | AG5: Makes | AH5: it | AI5: easy | AJ5: to | AK5: discuss | AL5: his | AM5: progress | AN5: with | AO5: his | AP5: doctor. | AQ5: This | AR5: journal | AS5: is | AT5: great | AU5: for | AV5: his | AW5: grandparents | AX5: who | AY5: watch | AZ5: him | BA5: while | BB5: I'm | BC5: gone. | BD5: Highly | BE5: recommend | BF5: this | BG5: journal | BH5: for | BI5: all | BJ5: parents | BK5: of | BL5: children | BM5: especially | BN5: for | BO5: those | BP5: with | BQ5: little | BR5: ones | BS5: under | BT5: a | BU5: year | BV5: of | BW5: age. | BX5: 1
A6: D4 | B6: My | C6: friend | D6: recommended | E6: this | F6: teether | G6: because | H6: her | I6: daughter | J6: loves | K6: it. | L6: However, | M6: my | N6: daughter | O6: loves | P6: throwing | Q6: it | R6: on | S6: to | T6: floor. | U6: Hopefully, | V6: it | W6: will | X6: work | Y6: better | Z6: for | AA6: you. | BX6: 0
A7: D5 | B7: Don't | C7: waste | D7: your | E7: money, | F7: my | G7: son | H7: would | I7: rather | J7: suck | K7: on | L7: his | M7: fingers | N7: than | O7: to | P7: use | Q7: this | R7: messaging | S7: to | T7: teether. | U7: The | V7: massager | W7: really | X7: has | Y7: to | Z7: be | AA7: squeezed | AB7: in | AC7: order | AD7: to | AE7: work. | BX7: 0
A8: D6 | B8: This | C8: is | D8: the | E8: best | F8: way | G8: to | H8: keep | I8: track | J8: of | K8: when | L8: your | M8: baby | N8: eats, | O8: sleeps, | P8: poops, | Q8: gets | R8: a | S8: to | T8: etc. | U8: It's | V8: also | W8: a | X8: great | Y8: way | Z8: to | AA8: keep | AB8: track | AC8: of | AD8: which | AE8: side | AF8: baby | AG8: nursed | AH8: on. | AI8: I | AJ8: took | AK8: this | AL8: to | AM8: all | AN8: infant | AO8: doc | AP8: appt. | AQ8: And | AR8: it's | AS8: a | AT8: great | AU8: gift! | BX8: 1
A9: D7 | B9: Inside | C9: is | D9: not | E9: nice | F9: and | G9: clean. | H9: All | I9: in | J9: all, | K9: it | L9: does | M9: not | N9: what | O9: is | P9: advertised | Q9: and | R9: keeps | S9: to | T9: sane | U9: on | V9: what | W9: was | X9: done | Y9: changed | Z9: when | BX9: 0
A10: D8 | B10: We | C10: bought | D10: these | E10: trucks | F10: for | G10: our | H10: 15 | I10: month. | J10: old | K10: daughter | L10: and | M10: 4 | N10: mo. | O10: old | P10: son- | Q10: We | R10: love | S10: to | T10: They | U10: are | V10: nesting | W10: which | X10: is | Y10: fun | Z10: for | AA10: our | AB10: daughter | AC10: to | AD10: look | AE10: underneath | AF10: the | AG10: trucks | AH10: to | AI10: find | AJ10: the | AK10: next | AL10: one | AM10: or | AN10: they | AO10: can | AP10: stack | AQ10: one | AR10: on | AS10: top | AT10: of | AU10: the | AV10: other | AW10: to | AX10: make | AY10: a | AZ10: tower. | BA10: Perfect | BB10: first | BC10: trucks! | BD10: And | BE10: they | BF10: aren't | BG10: too | BH10: big- | BI10: a | BJ10: perfect | BK10: size! | BX10: 1
A11: D9 | B11: My | C11: son's | D11: therapist | E11: brings | F11: this | G11: toy | H11: over | I11: and | J11: he | K11: just | L11: loves | M11: it. | N11: He | O11: loves | P11: to | Q11: move | R11: the | S11: to | T11: on | U11: the | V11: fire | W11: truck | X11: up | Y11: and | Z11: down. | AA11: This | AB11: is | AC11: one | AD11: of | AE11: his | AF11: favorite | AG11: toys | AH11: and | AI11: he | AJ11: doesn't | AK11: play | AL11: with | AM11: a | AN11: lot | AO11: of | AP11: baby | AQ11: and | AR11: toddler | AS11: toys | AT11: (gets | AU11: bored | AV11: easy). | BX11: ?
A12: D10 | B12: The | C12: layout | D12: of | E12: the | F12: hours | G12: are | H12: a | I12: little | J12: tricky. | K12: The | L12: print | M12: on | N12: each | O12: page | P12: is | Q12: a | R12: light | S12: to | T12: so | U12: trying | V12: to | W12: journal | X12: diapers, | Y12: bottles, | Z12: meds | AA12: in | AB12: the | AC12: middle | AD12: of | AE12: the | AF12: night | AG12: is | AH12: a | AI12: challenge. | AJ12: I | AK12: could | AL12: not | AM12: use | AN12: the | AO12: space | AP12: to | AQ12: make | AR12: more | AS12: notes | AT12: and | AU12: comment | AV12: on | AW12: something | AX12: cute | AY12: that | AZ12: day. | BX12: ?
A15: DOC.NO | B15: TOTAL WORD COUNT | C15: Class
A16: D1 | B16: =COUNTIF(B3:BW3,"<>") -> 46 | C16: 1
A17: D2 | B17: =COUNTIF(B4:BW4,"<>") -> 40 | C17: 1
A18: D3 | B18: =COUNTIF(B5:BW5,"<>") -> 74 | C18: 1
A19: D4 | B19: =COUNTIF(B6:BW6,"<>") -> 26 | C19: 0
A20: D5 | B20: =COUNTIF(B7:BW7,"<>") -> 30 | C20: 0
A21: D6 | B21: =COUNTIF(B8:BW8,"<>") -> 46 | C21: 1
A22: D7 | B22: =COUNTIF(B9:BW9,"<>") -> 25 | C22: 0
A23: D8 | B23: =COUNTIF(B10:BW10,"<>") -> 62 | C23: 1
A24: D9 | B24: =COUNTIF(B11:BW11,"<>") -> 47 | C24: ?
A25: D10 | B25: =COUNTIF(B12:BW12,"<>") -> 51 | C25: ?
A27: STEP-2:Punctual Removal(removed . , ! ( ) ' -)
A28: DOC N0 | B28: DOCUMENT | BX28: Class
A29: D1 | B29: This | C29: book | D29: is | E29: perfect | F29: Im | G29: a | H29: first | I29: time | J29: new | K29: mom | L29: and | M29: this | N29: book | O29: made | P29: it | Q29: so | R29: easy | S29: to | T29: keep | U29: track | V29: of | W29: feedings | X29: diaper | Y29: changes | Z29: sleep | AA29: Definitely | AB29: would | AC29: recommend | AD29: this | AE29: for | AF29: new | AG29: moms | AH29: Plus | AI29: its | AJ29: small | AK29: enough | AL29: that | AM29: I | AN29: throw | AO29: in | AP29: the | AQ29: diaper | AR29: back | AS29: for | AT29: doctor | AU29: visits | BX29: 1
A30: D2 | B30: I | C30: use | D30: this | E30: so | F30: that | G30: our | H30: babysitter | I30: grandma | J30: can | K30: keep | L30: track | M30: of | N30: what | O30: goes | P30: on | Q30: during | R30: the | S30: day | T30: Weve | U30: recorded | V30: so | W30: many | X30: milestones | Y30: since | Z30: we | AA30: received | AB30: this | AC30: Ill | AD30: definitely | AE30: get | AF30: another | AG30: one | AH30: in | AI30: 6 | AJ30: months | AK30: when | AL30: we | AM30: finish | AN30: this | AO30: book | BX30: 1
A31: D3 | B31: I | C31: have | D31: used | E31: this | F31: book | G31: since | H31: my | I31: son | J31: was | K31: born | L31: Its | M31: a | N31: great | O31: and | P31: handy | Q31: way | R31: to | S31: keep | T31: track | U31: of | V31: when | W31: and | X31: how | Y31: much | Z31: eats | AA31: and | AB31: when | AC31: I | AD31: change | AE31: his | AF31: diaper | AG31: Makes | AH31: it | AI31: easy | AJ31: to | AK31: discuss | AL31: his | AM31: progress | AN31: with | AO31: his | AP31: doctor | AQ31: This | AR31: journal | AS31: is | AT31: great | AU31: for | AV31: his | AW31: grandparents | AX31: who | AY31: watch | AZ31: him | BA31: while | BB31: Im | BC31: gone | BD31: Highly | BE31: recommend | BF31: this | BG31: journal | BH31: for | BI31: all | BJ31: parents | BK31: of | BL31: children | BM31: especially | BN31: for | BO31: those | BP31: with | BQ31: little | BR31: ones | BS31: under | BT31: a | BU31: year | BV31: of | BW31: age | BX31: 1
A32: D4 | B32: My | C32: friend | D32: recommended | E32: this | F32: teether | G32: because | H32: her | I32: daughter | J32: loves | K32: it | L32: However | M32: my | N32: daughter | O32: loves | P32: throwing | Q32: it | R32: on | S32: the | T32: floor | U32: Hopefully | V32: it | W32: will | X32: work | Y32: better | Z32: for | AA32: you | BX32: 0
A33: D5 | B33: Dont | C33: waste | D33: your | E33: money | F33: my | G33: son | H33: would | I33: rather | J33: suck | K33: on | L33: his | M33: fingers | N33: than | O33: to | P33: use | Q33: this | R33: messaging | S33: corn | T33: teether | U33: The | V33: massager | W33: really | X33: has | Y33: to | Z33: be | AA33: squeezed | AB33: in | AC33: order | AD33: to | AE33: work | BX33: 0
A34: D6 | B34: This | C34: is | D34: the | E34: best | F34: way | G34: to | H34: keep | I34: track | J34: of | K34: when | L34: your | M34: baby | N34: eats | O34: sleeps | P34: poops | Q34: gets | R34: a | S34: bath | T34: etc | U34: Its | V34: also | W34: a | X34: great | Y34: way | Z34: to | AA34: keep | AB34: track | AC34: of | AD34: which | AE34: side | AF34: baby | AG34: nursed | AH34: on | AI34: I | AJ34: took | AK34: this | AL34: to | AM34: all | AN34: infant | AO34: doc | AP34: appt | AQ34: And | AR34: its | AS34: a | AT34: great | AU34: gift | BX34: 1
A35: D7 | B35: Inside | C35: is | D35: not | E35: nice | F35: and | G35: clean | H35: All | I35: in | J35: all | K35: it | L35: does | M35: not | N35: what | O35: is | P35: advertised | Q35: and | R35: keeps | S35: us | T35: sane | U35: on | V35: what | W35: was | X35: done | Y35: changed | Z35: when | BX35: 0
A36: D8 | B36: We | C36: bought | D36: these | E36: trucks | F36: for | G36: our | H36: 15 | I36: month | J36: old | K36: daughter | L36: and | M36: 4 | N36: mo | O36: old | P36: son | Q36: We | R36: love | S36: them | T36: They | U36: are | V36: nesting | W36: which | X36: is | Y36: fun | Z36: for | AA36: our | AB36: daughter | AC36: to | AD36: look | AE36: underneath | AF36: the | AG36: trucks | AH36: to | AI36: find | AJ36: the | AK36: next | AL36: one | AM36: or | AN36: they | AO36: can | AP36: stack | AQ36: one | AR36: on | AS36: top | AT36: of | AU36: the | AV36: other | AW36: to | AX36: make | AY36: a | AZ36: tower | BA36: Perfect | BB36: first | BC36: trucks | BD36: And | BE36: they | BF36: arent | BG36: too | BH36: big | BI36: a | BJ36: perfect | BK36: size | BX36: 1
A37: D9 | B37: My | C37: sons | D37: therapist | E37: brings | F37: this | G37: toy | H37: over | I37: and | J37: he | K37: just | L37: loves | M37: it | N37: He | O37: loves | P37: to | Q37: move | R37: the | S37: ladder | T37: on | U37: the | V37: fire | W37: truck | X37: up | Y37: and | Z37: down | AA37: This | AB37: is | AC37: one | AD37: of | AE37: his | AF37: favorite | AG37: toys | AH37: and | AI37: he | AJ37: doesnt | AK37: play | AL37: with | AM37: a | AN37: lot | AO37: of | AP37: baby | AQ37: and | AR37: toddler | AS37: toys | AT37: gets | AU37: bored | AV37: easy | BX37: ?
A38: D10 | B38: The | C38: layout | D38: of | E38: the | F38: hours | G38: are | H38: a | I38: little | J38: tricky | K38: The | L38: print | M38: on | N38: each | O38: page | P38: is | Q38: a | R38: light | S38: grey | T38: so | U38: trying | V38: to | W38: journal | X38: diapers | Y38: bottles | Z38: meds | AA38: in | AB38: the | AC38: middle | AD38: of | AE38: the | AF38: night | AG38: is | AH38: a | AI38: challenge | AJ38: I | AK38: could | AL38: not | AM38: use | AN38: the | AO38: space | AP38: to | AQ38: make | AR38: more | AS38: notes | AT38: and | AU38: comment | AV38: on | AW38: something | AX38: cute | AY38: that | AZ38: day | BX38: ?
A40: STEP-3:Stop word Removal
A41: DOC N0 | B41: DOCUMENT | BX41: Class
A42: D1 | C42: book | E42: perfect | H42: first | I42: time | J42: new | K42: mom | N42: book | O42: made | R42: easy | T42: keep | U42: track | W42: feedings | X42: diaper | Y42: changes | Z42: sleep | AA42: Definitely | AC42: recommend | AF42: new | AG42: moms | AH42: Plus | AJ42: small | AK42: enough | AN42: throw | AQ42: diaper | AR42: back | AT42: doctor | AU42: visits | BX42: 1
A43: D2 | C43: use | H43: babysitter | I43: grandma | K43: keep | L43: track | S43: day | U43: recorded | W43: many | X43: milestones | AA43: received | AD43: definitely | AF43: another | AJ43: months | AM43: finish | AO43: book | BX43: 1
A44: D3 | D44: used | F44: book | G44: since | I44: son | K44: born | N44: great | P44: handy | Q44: way | S44: keep | T44: track | Z44: eats | AD44: change | AF44: diaper | AG44: Makes | AI44: easy | AK44: discuss | AM44: progress | AP44: doctor | AR44: journal | AT44: great | AW44: grandparents | AY44: watch | BC44: gone | BD44: Highly | BE44: recommend | BG44: journal | BJ44: parents | BL44: children | BM44: especially | BQ44: little | BR44: ones | BS44: under | BU44: year | BW44: age | BX44: 1
...

Sheet NAIVE BAYES text classification
A1: DOC NO | B1: CLASS | C1: WORDS IN CLASS1 | D1: WORD COUNT IN CLASS 1 | E1: TOTAL WORD IN C1 | F1: LIKELIHOOD IN CLASS C1 | G1: UNIQUE WORD | H1: WORD COUNT IN CLASS 0 | I1: TOTAL WORD IN C0 | J1: LIKELIHOOD IN CLASS C0 | P1: U NIQUE WORD
A2: D1 | B2: 1 | C2: book | D2: =COUNTIFS($C$2:$C$165,C2,$B$2:$B$165,1) -> 4 | E2: =COUNTIF($B$2:$B$165,1) -> 124 | F2: =(D2+$B$2)/($E$2+$G$2) -> 0.021645022 | G2: =COUNTIF($P$2:$P$108,"<>") -> 107 | H2: =COUNTIFS($C$2:$C$165,C2,$B$2:$B$165,0) -> 0 | I2: =COUNTIF($B$2:$B$165,0) -> 40 | J2: =(H2+$B$2)/($I$2+$G$2) -> 0.0068027211 | P2: {=_xlfn.UNIQUE(C2:C165)} -> book
B3: 1 | C3: perfect | D3: =COUNTIFS($C$2:$C$165,C3,$B$2:$B$165,1) -> 3 | E3: =COUNTIF($B$2:$B$165,1) -> 124 | F3: =(D3+$B$2)/($E$2+$G$2) -> 0.017316017 | G3: =COUNTIF($P$2:$P$108,"<>") -> 107 | H3: =COUNTIFS($C$2:$C$165,C3,$B$2:$B$165,0) -> 0 | I3: =COUNTIF($B$2:$B$165,0) -> 40 | J3: =(H3+$B$2)/($I$2+$G$2) -> 0.0068027211 | P3: perfect
B4: 1 | C4: first | D4: =COUNTIFS($C$2:$C$165,C4,$B$2:$B$165,1) -> 2 | E4: =COUNTIF($B$2:$B$165,1) -> 124 | F4: =(D4+$B$2)/($E$2+$G$2) -> 0.012987013 | G4: =COUNTIF($P$2:$P$108,"<>") -> 107 | H4: =COUNTIFS($C$2:$C$165,C4,$B$2:$B$165,0) -> 0 | I4: =COUNTIF($B$2:$B$165,0) -> 40 | J4: =(H4+$B$2)/($I$2+$G$2) -> 0.0068027211 | P4: first
B5: 1 | C5: time | D5: =COUNTIFS($C$2:$C$165,C5,$B$2:$B$165,1) -> 1 | E5: =COUNTIF($B$2:$B$165,1) -> 124 | F5: =(D5+$B$2)/($E$2+$G$2) -> 0.0086580087 | G5: =COUNTIF($P$2:$P$108,"<>") -> 107 | H5: =COUNTIFS($C$2:$C$165,C5,$B$2:$B$165,0) -> 0 | I5: =COUNTIF($B$2:$B$165,0) -> 40 | J5: =(H5+$B$2)/($I$2+$G$2) -> 0.0068027211 | P5: time
B6: 1 | C6: new | D6: =COUNTIFS($C$2:$C$165,C6,$B$2:$B$165,1) -> 2 | E6: =COUNTIF($B$2:$B$165,1) -> 124 | F6: =(D6+$B$2)/($E$2+$G$2) -> 0.012987013 | G6: =COUNTIF($P$2:$P$108,"<>") -> 107 | H6: =COUNTIFS($C$2:$C$165,C6,$B$2:$B$165,0) -> 0 | I6: =COUNTIF($B$2:$B$165,0) -> 40 | J6: =(H6+$B$2)/($I$2+$G$2) -> 0.0068027211 | P6: new
B7: 1 | C7: mom | D7: =COUNTIFS($C$2:$C$165,C7,$B$2:$B$165,1) -> 2 | E7: =COUNTIF($B$2:$B$165,1) -> 124 | F7: =(D7+$B$2)/($E$2+$G$2) -> 0.012987013 | G7: =COUNTIF($P$2:$P$108,"<>") -> 107 | H7: =COUNTIFS($C$2:$C$165,C7,$B$2:$B$165,0) -> 0 | I7: =COUNTIF($B$2:$B$165,0) -> 40 | J7: =(H7+$B$2)/($I$2+$G$2) -> 0.0068027211 | P7: mom
B8: 1 | C8: book | D8: =COUNTIFS($C$2:$C$165,C8,$B$2:$B$165,1) -> 4 | E8: =COUNTIF($B$2:$B$165,1) -> 124 | F8: =(D8+$B$2)/($E$2+$G$2) -> 0.021645022 | G8: =COUNTIF($P$2:$P$108,"<>") -> 107 | H8: =COUNTIFS($C$2:$C$165,C8,$B$2:$B$165,0) -> 0 | I8: =COUNTIF($B$2:$B$165,0) -> 40 | J8: =(H8+$B$2)/($I$2+$G$2) -> 0.0068027211 | P8: made
B9: 1 | C9: made | D9: =COUNTIFS($C$2:$C$165,C9,$B$2:$B$165,1) -> 1 | E9: =COUNTIF($B$2:$B$165,1) -> 124 | F9: =(D9+$B$2)/($E$2+$G$2) -> 0.0086580087 | G9: =COUNTIF($P$2:$P$108,"<>") -> 107 | H9: =COUNTIFS($C$2:$C$165,C9,$B$2:$B$165,0) -> 0 | I9: =COUNTIF($B$2:$B$165,0) -> 40 | J9: =(H9+$B$2)/($I$2+$G$2) -> 0.0068027211 | P9: easy
B10: 1 | C10: easy | D10: =COUNTIFS($C$2:$C$165,C10,$B$2:$B$165,1) -> 2 | E10: =COUNTIF($B$2:$B$165,1) -> 124 | F10: =(D10+$B$2)/($E$2+$G$2) -> 0.012987013 | G10: =COUNTIF($P$2:$P$108,"<>") -> 107 | H10: =COUNTIFS($C$2:$C$165,C10,$B$2:$B$165,0) -> 0 | I10: =COUNTIF($B$2:$B$165,0) -> 40 | J10: =(H10+$B$2)/($I$2+$G$2) -> 0.0068027211 | P10: keep
B11: 1 | C11: keep | D11: =COUNTIFS($C$2:$C$165,C11,$B$2:$B$165,1) -> 5 | E11: =COUNTIF($B$2:$B$165,1) -> 124 | F11: =(D11+$B$2)/($E$2+$G$2) -> 0.025974026 | G11: =COUNTIF($P$2:$P$108,"<>") -> 107 | H11: =COUNTIFS($C$2:$C$165,C11,$B$2:$B$165,0) -> 1 | I11: =COUNTIF($B$2:$B$165,0) -> 40 | J11: =(H11+$B$2)/($I$2+$G$2) -> 0.013605442 | P11: track
B12: 1 | C12: track | D12: =COUNTIFS($C$2:$C$165,C12,$B$2:$B$165,1) -> 5 | E12: =COUNTIF($B$2:$B$165,1) -> 124 | F12: =(D12+$B$2)/($E$2+$G$2) -> 0.025974026 | G12: =COUNTIF($P$2:$P$108,"<>") -> 107 | H12: =COUNTIFS($C$2:$C$165,C12,$B$2:$B$165,0) -> 0 | I12: =COUNTIF($B$2:$B$165,0) -> 40 | J12: =(H12+$B$2)/($I$2+$G$2) -> 0.0068027211 | P12: feeding
B13: 1 | C13: feeding | D13: =COUNTIFS($C$2:$C$165,C13,$B$2:$B$165,1) -> 1 | E13: =COUNTIF($B$2:$B$165,1) -> 124 | F13: =(D13+$B$2)/($E$2+$G$2) -> 0.0086580087 | G13: =COUNTIF($P$2:$P$108,"<>") -> 107 | H13: =COUNTIFS($C$2:$C$165,C13,$B$2:$B$165,0) -> 0 | I13: =COUNTIF($B$2:$B$165,0) -> 40 | J13: =(H13+$B$2)/($I$2+$G$2) -> 0.0068027211 | P13: diaper
B14: 1 | C14: diaper | D14: =COUNTIFS($C$2:$C$165,C14,$B$2:$B$165,1) -> 3 | E14: =COUNTIF($B$2:$B$165,1) -> 124 | F14: =(D14+$B$2)/($E$2+$G$2) -> 0.017316017 | G14: =COUNTIF($P$2:$P$108,"<>") -> 107 | H14: =COUNTIFS($C$2:$C$165,C14,$B$2:$B$165,0) -> 0 | I14: =COUNTIF($B$2:$B$165,0) -> 40 | J14: =(H14+$B$2)/($I$2+$G$2) -> 0.0068027211 | P14: change
... B27: 1 | C27: doctor | D27: =COUNTIFS($C$2:$C$165,C27,$B$2:$B$165,1) -> 3 | E27: =COUNTIF($B$2:$B$165,1) -> 124 | F27: =(D27+$B$2)/($E$2+$G$2) -> 0.017316017 | G27: =COUNTIF($P$2:$P$108,"<>") -> 107 | H27: =COUNTIFS($C$2:$C$165,C27,$B$2:$B$165,0) -> 0 | I27: =COUNTIF($B$2:$B$165,0) -> 40 | J27: =(H27+$B$2)/($I$2+$G$2) -> 0.0068027211 | P27: day
A28: D2 | B28: 1 | C28: use | D28: =COUNTIFS($C$2:$C$165,C28,$B$2:$B$165,1) -> 2 | E28: =COUNTIF($B$2:$B$165,1) -> 124 | F28: =(D28+$B$2)/($E$2+$G$2) -> 0.012987013 | G28: =COUNTIF($P$2:$P$108,"<>") -> 107 | H28: =COUNTIFS($C$2:$C$165,C28,$B$2:$B$165,0) -> 1 | I28: =COUNTIF($B$2:$B$165,0) -> 40 | J28: =(H28+$B$2)/($I$2+$G$2) -> 0.013605442 | P28: record
B29: 1 | C29: babysitter | D29: =COUNTIFS($C$2:$C$165,C29,$B$2:$B$165,1) -> 1 | E29: =COUNTIF($B$2:$B$165,1) -> 124 | F29: =(D29+$B$2)/($E$2+$G$2) -> 0.0086580087 | G29: =COUNTIF($P$2:$P$108,"<>") -> 107 | H29: =COUNTIFS($C$2:$C$165,C29,$B$2:$B$165,0) -> 0 | I29: =COUNTIF($B$2:$B$165,0) -> 40 | J29: =(H29+$B$2)/($I$2+$G$2) -> 0.0068027211 | P29: many
B30: 1 | C30: grandma | D30: =COUNTIFS($C$2:$C$165,C30,$B$2:$B$165,1) -> 1 | E30: =COUNTIF($B$2:$B$165,1) -> 124 | F30: =(D30+$B$2)/($E$2+$G$2) -> 0.0086580087 | G30: =COUNTIF($P$2:$P$108,"<>") -> 107 | H30: =COUNTIFS($C$2:$C$165,C30,$B$2:$B$165,0) -> 0 | I30: =COUNTIF($B$2:$B$165,0) -> 40 | J30: =(H30+$B$2)/($I$2+$G$2) -> 0.0068027211 | P30: milestone
B31: 1 | C31: keep | D31: =COUNTIFS($C$2:$C$165,C31,$B$2:$B$165,1) -> 5 | E31: =COUNTIF($B$2:$B$165,1) -> 124 | F31: =(D31+$B$2)/($E$2+$G$2) -> 0.025974026 | G31: =COUNTIF($P$2:$P$108,"<>") -> 107 | H31: =COUNTIFS($C$2:$C$165,C31,$B$2:$B$165,0) -> 1 | I31: =COUNTIF($B$2:$B$165,0) -> 40 | J31: =(H31+$B$2)/($I$2+$G$2) -> 0.013605442 | P31: receive
B32: 1 | C32: track | D32: =COUNTIFS($C$2:$C$165,C32,$B$2:$B$165,1) -> 5 | E32: =COUNTIF($B$2:$B$165,1) -> 124 | F32: =(D32+$B$2)/($E$2+$G$2) -> 0.025974026 | G32: =COUNTIF($P$2:$P$108,"<>") -> 107 | H32: =COUNTIFS($C$2:$C$165,C32,$B$2:$B$165,0) -> 0 | I32: =COUNTIF($B$2:$B$165,0) -> 40 | J32: =(H32+$B$2)/($I$2+$G$2) -> 0.0068027211 | P32: definite
B33: 1 | C33: day | D33: =COUNTIFS($C$2:$C$165,C33,$B$2:$B$165,1) -> 1 | E33: =COUNTIF($B$2:$B$165,1) -> 124 | F33: =(D33+$B$2)/($E$2+$G$2) -> 0.0086580087 | G33: =COUNTIF($P$2:$P$108,"<>") -> 107 | H33: =COUNTIFS($C$2:$C$165,C33,$B$2:$B$165,0) -> 0 | I33: =COUNTIF($B$2:$B$165,0) -> 40 | J33: =(H33+$B$2)/($I$2+$G$2) -> 0.0068027211 | P33: get
B34: 1 | C34: record | D34: =COUNTIFS($C$2:$C$165,C34,$B$2:$B$165,1) -> 1 | E34: =COUNTIF($B$2:$B$165,1) -> 124 | F34: =(D34+$B$2)/($E$2+$G$2) -> 0.0086580087 | G34: =COUNTIF($P$2:$P$108,"<>") -> 107 | H34: =COUNTIFS($C$2:$C$165,C34,$B$2:$B$165,0) -> 0 | I34: =COUNTIF($B$2:$B$165,0) -> 40 | J34: =(H34+$B$2)/($I$2+$G$2) -> 0.0068027211 | P34: another
B35: 1 | C35: many | D35: =COUNTIFS($C$2:$C$165,C35,$B$2:$B$165,1) -> 1 | E35: =COUNTIF($B$2:$B$165,1) -> 124 | F35: =(D35+$B$2)/($E$2+$G$2) -> 0.0086580087 | G35: =COUNTIF($P$2:$P$108,"<>") -> 107 | H35: =COUNTIFS($C$2:$C$165,C35,$B$2:$B$165,0) -> 0 | I35: =COUNTIF($B$2:$B$165,0) -> 40 | J35: =(H35+$B$2)/($I$2+$G$2) -> 0.0068027211 | M35: #VALUE! | P35: one
B36: 1 | C36: milestone | D36: =COUNTIFS($C$2:$C$165,C36,$B$2:$B$165,1) -> 1 | E36: =COUNTIF($B$2:$B$165,1) -> 124 | F36: =(D36+$B$2)/($E$2+$G$2) -> 0.0086580087 | G36: =COUNTIF($P$2:$P$108,"<>") -> 107 | H36: =COUNTIFS($C$2:$C$165,C36,$B$2:$B$165,0) -> 0 | I36: =COUNTIF($B$2:$B$165,0) -> 40 | J36: =(H36+$B$2)/($I$2+$G$2) -> 0.0068027211 | P36: month
B37: 1 | C37: receive | D37: =COUNTIFS($C$2:$C$165,C37,$B$2:$B$165,1) -> 1 | E37: =COUNTIF($B$2:$B$165,1) -> 124 | F37: =(D37+$B$2)/($E$2+$G$2) -> 0.0086580087 | G37: =COUNTIF($P$2:$P$108,"<>") -> 107 | H37: =COUNTIFS($C$2:$C$165,C37,$B$2:$B$165,0) -> 0 | I37: =COUNTIF($B$2:$B$165,0) -> 40 | J37: =(H37+$B$2)/($I$2+$G$2) -> 0.0068027211 | P37: finish
B38: 1 | C38: definite | D38: =COUNTIFS($C$2:$C$165,C38,$B$2:$B$165,1) -> 1 | E38: =COUNTIF($B$2:$B$165,1) -> 124 | F38: =(D38+$B$2)/($E$2+$G$2) -> 0.0086580087 | G38: =COUNTIF($P$2:$P$108,"<>") -> 107 | H38: =COUNTIFS($C$2:$C$165,C38,$B$2:$B$165,0) -> 0 | I38: =COUNTIF($B$2:$B$165,0) -> 40 | J38: =(H38+$B$2)/($I$2+$G$2) -> 0.0068027211 | P38: since
B39: 1 | C39: get | D39: =COUNTIFS($C$2:$C$165,C39,$B$2:$B$165,1) -> 2 | E39: =COUNTIF($B$2:$B$165,1) -> 124 | F39: =(D39+$B$2)/($E$2+$G$2) -> 0.012987013 | G39: =COUNTIF($P$2:$P$108,"<>") -> 107 | H39: =COUNTIFS($C$2:$C$165,C39,$B$2:$B$165,0) -> 0 | I39: =COUNTIF($B$2:$B$165,0) -> 40 | J39: =(H39+$B$2)/($I$2+$G$2) -> 0.0068027211 | P39: son
B40: 1 | C40: another | D40: =COUNTIFS($C$2:$C$165,C40,$B$2:$B$165,1) -> 1 | E40: =COUNTIF($B$2:$B$165,1) -> 124 | F40: =(D40+$B$2)/($E$2+$G$2) -> 0.0086580087 | G40: =COUNTIF($P$2:$P$108,"<>") -> 107 | H40: =COUNTIFS($C$2:$C$165,C40,$B$2:$B$165,0) -> 0 | I40: =COUNTIF($B$2:$B$165,0) -> 40 | J40: =(H40+$B$2)/($I$2+$G$2) -> 0.0068027211 | P40: born
B41: 1 | C41: one | D41: =COUNTIFS($C$2:$C$165,C41,$B$2:$B$165,1) -> 3 | E41: =COUNTIF($B$2:$B$165,1) -> 124 | F41: =(D41+$B$2)/($E$2+$G$2) -> 0.017316017 | G41: =COUNTIF($P$2:$P$108,"<>") -> 107 | H41: =COUNTIFS($C$2:$C$165,C41,$B$2:$B$165,0) -> 0 | I41: =COUNTIF($B$2:$B$165,0) -> 40 | J41: =(H41+$B$2)/($I$2+$G$2) -> 0.0068027211 | P41: great
B42: 1 | C42: month | D42: =COUNTIFS($C$2:$C$165,C42,$B$2:$B$165,1) -> 2 | E42: =COUNTIF($B$2:$B$165,1) -> 124 | F42: =(D42+$B$2)/($E$2+$G$2) -> 0.012987013 | G42: =COUNTIF($P$2:$P$108,"<>") -> 107 | H42: =COUNTIFS($C$2:$C$165,C42,$B$2:$B$165,0) -> 0 | I42: =COUNTIF($B$2:$B$165,0) -> 40 | J42: =(H42+$B$2)/($I$2+$G$2) -> 0.0068027211 | P42: handy
B43: 1 | C43: finish | D43: =COUNTIFS($C$2:$C$165,C43,$B$2:$B$165,1) -> 1 | E43: =COUNTIF($B$2:$B$165,1) -> 124 | F43: =(D43+$B$2)/($E$2+$G$2) -> 0.0086580087 | G43: =COUNTIF($P$2:$P$108,"<>") -> 107 | H43: =COUNTIFS($C$2:$C$165,C43,$B$2:$B$165,0) -> 0 | I43: =COUNTIF($B$2:$B$165,0) -> 40 | J43: =(H43+$B$2)/($I$2+$G$2) -> 0.0068027211 | P43: way
B44: 1 | C44: book | D44: =COUNTIFS($C$2:$C$165,C44,$B$2:$B$165,1) -> 4 | E44: =COUNTIF($B$2:$B$165,1) -> 124 | F44: =(D44+$B$2)/($E$2+$G$2) -> 0.021645022 | G44: =COUNTIF($P$2:$P$108,"<>") -> 107 | H44: =COUNTIFS($C$2:$C$165,C44,$B$2:$B$165,0) -> 0 | I44: =COUNTIF($B$2:$B$165,0) -> 40 | J44: =(H44+$B$2)/($I$2+$G$2) -> 0.0068027211 | P44: eat
A45: D3 | B45: 1 | C45: use | D45: =COUNTIFS($C$2:$C$165,C45,$B$2:$B$165,1) -> 2 | E45: =COUNTIF($B$2:$B$165,1) -> 124 | F45: =(D45+$B$2)/($E$2+$G$2) -> 0.012987013 | G45: =COUNTIF($P$2:$P$108,"<>") -> 107 | H45: =COUNTIFS($C$2:$C$165,C45,$B$2:$B$165,0) -> 1 | I45: =COUNTIF($B$2:$B$165,0) -> 40 | J45: =(H45+$B$2)/($I$2+$G$2) -> 0.013605442 | P45: make
B46: 1 | C46: book | D46: =COUNTIFS($C$2:$C$165,C46,$B$2:$B$165,1) -> 4 | E46: =COUNTIF($B$2:$B$165,1) -> 124 | F46: =(D46+$B$2)/($E$2+$G$2) -> 0.021645022 | G46: =COUNTIF($P$2:$P$108,"<>") -> 107 | H46: =COUNTIFS($C$2:$C$165,C46,$B$2:$B$165,0) -> 0 | I46: =COUNTIF($B$2:$B$165,0) -> 40 | J46: =(H46+$B$2)/($I$2+$G$2) -> 0.0068027211 | P46: discuss
B47: 1 | C47: since | D47: =COUNTIFS($C$2:$C$165,C47,$B$2:$B$165,1) -> 1 | E47: =COUNTIF($B$2:$B$165,1) -> 124 | F47: =(D47+$B$2)/($E$2+$G$2) -> 0.0086580087 | G47: =COUNTIF($P$2:$P$108,"<>") -> 107 | H47: =COUNTIFS($C$2:$C$165,C47,$B$2:$B$165,0) -> 0 | I47: =COUNTIF($B$2:$B$165,0) -> 40 | J47: =(H47+$B$2)/($I$2+$G$2) -> 0.0068027211 | P47: progress
B48: 1 | C48: son | D48: =COUNTIFS($C$2:$C$165,C48,$B$2:$B$165,1) -> 2 | E48: =COUNTIF($B$2:$B$165,1) -> 124 | F48: =(D48+$B$2)/($E$2+$G$2) -> 0.012987013 | G48: =COUNTIF($P$2:$P$108,"<>") -> 107 | H48: =COUNTIFS($C$2:$C$165,C48,$B$2:$B$165,0) -> 1 | I48: =COUNTIF($B$2:$B$165,0) -> 40 | J48: =(H48+$B$2)/($I$2+$G$2) -> 0.013605442 | P48: journal
B49: 1 | C49: born | D49: =COUNTIFS($C$2:$C$165,C49,$B$2:$B$165,1) -> 1 | E49: =COUNTIF($B$2:$B$165,1) -> 124 | F49: =(D49+$B$2)/($E$2+$G$2) -> 0.0086580087 | G49: =COUNTIF($P$2:$P$108,"<>") -> 107 | H49: =COUNTIFS($C$2:$C$165,C49,$B$2:$B$165,0) -> 0 | I49: =COUNTIF($B$2:$B$165,0) -> 40 | J49: =(H49+$B$2)/($I$2+$G$2) -> 0.0068027211 | P49: grandparent
B50: 1 | C50: great | D50: =COUNTIFS($C$2:$C$165,C50,$B$2:$B$165,1) -> 4 | E50: =COUNTIF($B$2:$B$165,1) -> 124 | F50: =(D50+$B$2)/($E$2+$G$2) -> 0.021645022 | G50: =COUNTIF($P$2:$P$108,"<>") -> 107 | H50: =COUNTIFS($C$2:$C$165,C50,$B$2:$B$165,0) -> 0 | I50: =COUNTIF($B$2:$B$165,0) -> 40 | J50: =(H50+$B$2)/($I$2+$G$2) -> 0.0068027211 | P50: watch
B51: 1 | C51: handy | D51: =COUNTIFS($C$2:$C$165,C51,$B$2:$B$165,1) -> 1 | E51: =COUNTIF($B$2:$B$165,1) -> 124 | F51: =(D51+$B$2)/($E$2+$G$2) -> 0.0086580087 | G51: =COUNTIF($P$2:$P$108,"<>") -> 107 | H51: =COUNTIFS($C$2:$C$165,C51,$B$2:$B$165,0) -> 0 | I51: =COUNTIF($B$2:$B$165,0) -> 40 | J51: =(H51+$B$2)/($I$2+$G$2) -> 0.0068027211 | P51: highly
B52: 1 | C52: way | D52: =COUNTIFS($C$2:$C$165,C52,$B$2:$B$165,1) -> 3 | E52: =COUNTIF($B$2:$B$165,1) -> 124 | F52: =(D52+$B$2)/($E$2+$G$2) -> 0.017316017 | G52: =COUNTIF($P$2:$P$108,"<>") -> 107 | H52: =COUNTIFS($C$2:$C$165,C52,$B$2:$B$165,0) -> 0 | I52: =COUNTIF($B$2:$B$165,0) -> 40 | J52: =(H52+$B$2)/($I$2+$G$2) -> 0.0068027211 | P52: parent
...

Sheet DESIRED CLASS
A1: D9 | B1: son | C1: therapist | D1: bring | E1: toy | F1: love | G1: love | H1: move | I1: ladder | J1: fire | K1: truck | L1: favorite | M1: toy | N1: does | O1: not | P1: play | Q1: baby | R1: toddler | S1: toys | T1: bore | U1: easy | AC1: ?
A2: D10 | B2: layout | C2: hour | D2: little | E2: tricky | F2: print | G2: page | H2: light | I2: grey | J2: journal | K2: diaper | L2: bottle | M2: med | N2: middle | O2: night | P2: challenge | Q2: could | R2: not | S2: use | T2: space | U2: make | V2: more | W2: note | X2: comment | Y2: something | Z2: cute | AA2: day | AC2: ?
J3: Prior probability computation:
B4: Posterior probability computation | J4: P(C1) | K4: NO OF DOCUMENT IN CLASS 1 /TOTAL NO OF DOCUMENTS IN CLASS 1 AND 0 | R4: (3/6)
J5: P(C0) | K5: NO OF DOCUMENT IN CLASS 0 /TOTAL NO OF DOCUMENTS IN CLASS 1 AND 0 | R5: (3/6)
J6: P(C1) | K6: =R4 -> (3/6) | L6: =5/8 -> 0.625 | N6: TOTAL WORDSIN C1 | P6: ='NAIVE BAYES text classification'!E2 -> 124 | R6: UNIQUE WORD COUNT | U6: ='NAIVE BAYES text classification'!G2 -> 107 | W6: 1
J7: P(C0) | K7: =R5 -> (3/6) | L7: =3/8 -> 0.375 | N7: TOTAL WORDSIN C0 | P7: ='NAIVE BAYES text classification'!I2 -> 40
I9: D9 | J9: P(C1/D9) | K9: son | L9: therapist | M9: bring | N9: toy | O9: love | P9: love | Q9: move | R9: ladder | S9: fire | T9: truck | U9: favorite | V9: toy | W9: does | X9: not | Y9: play | Z9: baby | AA9: toddler | AB9: toy | AC9: bore | AD9: easy
K10: =COUNTIFS(Table2[WORDS IN CLASS1],'DESIRED CLASS'!K9,Table2[CLASS],1) -> 2 | L10: =COUNTIFS(Table2[WORD COUNT IN CLASS 1],'DESIRED CLASS'!L9,Table2[WORDS IN CLASS1],1) -> 0 | M10: =COUNTIFS(Table2[TOTAL WORD IN C1],'DESIRED CLASS'!M9,Table2[WORD COUNT IN CLASS 1],1) -> 0 | N10: =COUNTIFS(Table2[LIKELIHOOD IN CLASS C1],'DESIRED CLASS'!N9,Table2[TOTAL WORD IN C1],1) -> 0 | O10: =COUNTIFS(Table2[UNIQUE WORD],'DESIRED CLASS'!O9,Table2[LIKELIHOOD IN CLASS C1],1) -> 0 | P10: =COUNTIFS(Table2[WORD COUNT IN CLASS 0],'DESIRED CLASS'!P9,Table2[UNIQUE WORD],1) -> 0 | Q10: =COUNTIFS(Table2[TOTAL WORD IN C0],'DESIRED CLASS'!Q9,Table2[WORD COUNT IN CLASS 0],1) -> 0 | R10: =COUNTIFS(Table2[LIKELIHOOD IN CLASS C0],'DESIRED CLASS'!R9,Table2[TOTAL WORD IN C0],1) -> 0 | S10: =COUNTIFS(Table2[DOC NO],'DESIRED CLASS'!S9,Table2[LIKELIHOOD IN CLASS C0],1) -> 0 | T10: =COUNTIFS(Table2[CLASS],'DESIRED CLASS'!T9,Table2[DOC NO],1) -> 0 | U10: =COUNTIFS(Table2[WORDS IN CLASS1],'DESIRED CLASS'!U9,Table2[CLASS],1) -> 0 | V10: =COUNTIFS(Table2[WORD COUNT IN CLASS 1],'DESIRED CLASS'!V9,Table2[WORDS IN CLASS1],1) -> 0 | W10: =COUNTIFS(Table2[TOTAL WORD IN C1],'DESIRED CLASS'!W9,Table2[WORD COUNT IN CLASS 1],1) -> 0 | X10: =COUNTIFS(Table2[WORD COUNT IN CLASS 1],'DESIRED CLASS'!X9,Table2[WORDS IN CLASS1],1) -> 0 | Y10: =COUNTIFS(Table2[TOTAL WORD IN C1],'DESIRED CLASS'!Y9,Table2[WORD COUNT IN CLASS 1],1) -> 0 | Z10: =COUNTIFS(Table2[WORD COUNT IN CLASS 1],'DESIRED CLASS'!Z9,Table2[WORDS IN CLASS1],1) -> 0 | AA10: =COUNTIFS(Table2[TOTAL WORD IN C1],'DESIRED CLASS'!AA9,Table2[WORD COUNT IN CLASS 1],1) -> 0 | AB10: =COUNTIFS(Table2[WORD COUNT IN CLASS 1],'DESIRED CLASS'!AB9,Table2[WORDS IN CLASS1],1) -> 0 | AC10: =COUNTIFS(Table2[TOTAL WORD IN C1],'DESIRED CLASS'!AC9,Table2[WORD COUNT IN CLASS 1],1) -> 0 | AD10: =COUNTIFS(Table2[TOTAL WORD IN C1],'DESIRED CLASS'!AD9,Table2[WORD COUNT IN CLASS 1],1) -> 0
I11: likelihood | J11: P(W/C1) | K11: =K10+$W$6/($P$6+$U$6) -> 2.004329 | L11: =L10+$W$6/($P$6+$U$6) -> 0.0043290043 | M11: =M10+$W$6/($P$6+$U$6) -> 0.0043290043 | N11: =N10+$W$6/($P$6+$U$6) -> 0.0043290043 | O11: =O10+$W$6/($P$6+$U$6) -> 0.0043290043 | P11: =P10+$W$6/($P$6+$U$6) -> 0.0043290043 | Q11: =Q10+$W$6/($P$6+$U$6) -> 0.0043290043 | R11: =R10+$W$6/($P$6+$U$6) -> 0.0043290043 | ... AD11: =AD10+$W$6/($P$6+$U$6) -> 0.0043290043
J12: P(C1/D9) | K12: =(L6*K11*L11*M11*N11*O11*P11*Q11*R11*S11*T11*U11*V11*W11*X11*Y11*Z11*AA11*AB11*AC11*AD11) -> 1.5460424e-45
J14: P(C0/D9) | K14: son | L14: therapist | M14: bring | N14: toy | O14: love | P14: love | Q14: move | R14: ladder | S14: fire | T14: truck | U14: favorite | V14: toy | W14: does | X14: not | Y14: play | Z14: baby | AA14: toddler | AB14: toys | AC14: bore | AD14: easy
B15: DESIRED CLASS | K15: =COUNTIFS(Table2[WORDS IN CLASS1],'DESIRED CLASS'!K14,Table2[CLASS],0) -> 1 | L15: =COUNTIFS(Table2[WORDS IN CLASS1],'DESIRED CLASS'!L14,Table2[CLASS],0) -> 0 | M15: =COUNTIFS(Table2[WORDS IN CLASS1],'DESIRED CLASS'!M14,Table2[CLASS],0) -> 0 | N15: =COUNTIFS(Table2[WORDS IN CLASS1],'DESIRED CLASS'!N14,Table2[CLASS],0) -> 0 | O15: =COUNTIFS(Table2[WORDS IN CLASS1],'DESIRED CLASS'!O14,Table2[CLASS],0) -> 2 | P15: =COUNTIFS(Table2[WORDS IN CLASS1],'DESIRED CLASS'!P14,Table2[CLASS],0) -> 2 | Q15: =COUNTIFS(Table2[WORDS IN CLASS1],'DESIRED CLASS'!Q14,Table2[CLASS],0) -> 0 | R15: =COUNTIFS(Table2[WORDS IN CLASS1],'DESIRED CLASS'!R14,Table2[CLASS],0) -> 0 | S15: =COUNTIFS(Table2[DOC NO],'DESIRED CLASS'!S14,Table2[LIKELIHOOD IN CLASS C0],0) -> 0 | T15: =COUNTIFS(Table2[WORDS IN CLASS1],'DESIRED CLASS'!T14,Table2[CLASS],0) -> 0 | U15: =COUNTIFS(Table2[WORDS IN CLASS1],'DESIRED CLASS'!U14,Table2[CLASS],0) -> 0 | V15: =COUNTIFS(Table2[WORDS IN CLASS1],'DESIRED CLASS'!V14,Table2[CLASS],0) -> 0 | W15: =COUNTIFS(Table2[WORDS IN CLASS1],'DESIRED CLASS'!W14,Table2[CLASS],0) -> 0 | X15: =COUNTIFS(Table2[WORDS IN CLASS1],'DESIRED CLASS'!X14,Table2[CLASS],0) -> 3 | Y15: =COUNTIFS(Table2[WORDS IN CLASS1],'DESIRED CLASS'!Y14,Table2[CLASS],0) -> 0 | Z15: =COUNTIFS(Table2[WORD COUNT IN CLASS 0],'DESIRED CLASS'!Z14,Table2[UNIQUE WORD],0) -> 0 | AA15: =COUNTIFS(Table2[TOTAL WORD IN C0],'DESIRED CLASS'!AA14,Table2[WORD COUNT IN CLASS 0],0) -> 0 | AB15: =COUNTIFS(Table2[LIKELIHOOD IN CLASS C0],'DESIRED CLASS'!AB14,Table2[TOTAL WORD IN C0],0) -> 0 | AC15: =COUNTIFS(Table2[TOTAL WORD IN C0],'DESIRED CLASS'!AC14,Table2[WORD COUNT IN CLASS 0],0) -> 0 | AD15: =COUNTIFS(Table2[TOTAL WORD IN C0],'DESIRED CLASS'!AD14,Table2[WORD COUNT IN CLASS 0],0) -> 0
B16: D9 | C16: =MAX(K12,K17) -> 9.6164015e-35 | D16: C0 | I16: likelihood | J16: P(W/C0) | K16: =K15+$W$6/($P$7+$U$6) -> 1.0068027 | L16: =L15+$W$6/($P$7+$U$6) -> 0.0068027211 | M16: =M15+$W$6/($P$7+$U$6) -> 0.0068027211 | N16: =N15+$W$6/($P$7+$U$6) -> 0.0068027211 | O16: =O15+$W$6/($P$7+$U$6) -> 2.0068027 | P16: =P15+$W$6/($P$7+$U$6) -> 2.0068027 | Q16: =Q15+$W$6/($P$7+$U$6) -> 0.0068027211 | R16: =R15+$W$6/($P$7+$U$6) -> 0.0068027211 | ... AD16: =AD15+$W$6/($P$7+$U$6) -> 0.0068027211
B17: D10 | C17: =MAX(K22,K27) -> 1.1689918e-49 | D17: C1 | J17: P(C0/D9) | K17: =L7*K16*L16*M16*N16*O16*P16*Q16*R16*S16*T16*U16*V16*W16*X16*Y16*Z16*AA16*AB16*AC16*AD16 -> 9.6164015e-35
I19: D10 | J19: P(C1/D10) | K19: layout | L19: hour | M19: little | N19: tricky | O19: print | P19: page | Q19: light | R19: grey | S19: journal | T19: diaper | U19: bottle | V19: med | W19: middle | X19: night | Y19: challenge | Z19: could | AA19: not | AB19: use | AC19: space | AD19: make | AE19: more | AF19: note | AG19: comment | AH19: something | AI19: cute | AJ19: day
K20: =COUNTIFS(Table2[WORDS IN CLASS1],'DESIRED CLASS'!K19,Table2[CLASS],1) -> 0 | L20: =COUNTIFS(Table2[WORDS IN CLASS1],'DESIRED CLASS'!L19,Table2[CLASS],1) -> 0 | M20: =COUNTIFS(Table2[TOTAL WORD IN C1],'DESIRED CLASS'!M19,Table2[WORD COUNT IN CLASS 1],1) -> 0 | N20: =COUNTIFS(Table2[WORDS IN CLASS1],'DESIRED CLASS'!N19,Table2[CLASS],1) -> 0 | O20: =COUNTIFS(Table2[WORDS IN CLASS1],'DESIRED CLASS'!O19,Table2[CLASS],1) -> 0 | P20: =COUNTIFS(Table2[WORDS IN CLASS1],'DESIRED CLASS'!P19,Table2[CLASS],1) -> 0 | Q20: =COUNTIFS(Table2[WORDS IN CLASS1],'DESIRED CLASS'!Q19,Table2[CLASS],1) -> 0 | R20: =COUNTIFS(Table2[WORDS IN CLASS1],'DESIRED CLASS'!R19,Table2[CLASS],1) -> 0 | S20: =COUNTIFS(Table2[WORDS IN CLASS1],'DESIRED CLASS'!S19,Table2[CLASS],1) -> 2 | T20: =COUNTIFS(Table2[CLASS],'DESIRED CLASS'!T19,Table2[DOC NO],1) -> 0 | U20: =COUNTIFS(Table2[WORDS IN CLASS1],'DESIRED CLASS'!U19,Table2[CLASS],1) -> 0 | V20: =COUNTIFS(Table2[WORDS IN CLASS1],'DESIRED CLASS'!V19,Table2[CLASS],1) -> 0 | W20: =COUNTIFS(Table2[WORDS IN CLASS1],'DESIRED CLASS'!W19,Table2[CLASS],1) -> 0 | X20: =COUNTIFS(Table2[WORDS IN CLASS1],'DESIRED CLASS'!X19,Table2[CLASS],1) -> 0 | Y20: =COUNTIFS(Table2[WORDS IN CLASS1],'DESIRED CLASS'!Y19,Table2[CLASS],1) -> 0 | Z20: =COUNTIFS(Table2[WORDS IN CLASS1],'DESIRED CLASS'!Z19,Table2[CLASS],1) -> 0 | AA20: =COUNTIFS(Table2[WORDS IN CLASS1],'DESIRED CLASS'!AA19,Table2[CLASS],1) -> 0 | AB20: =COUNTIFS(Table2[WORDS IN CLASS1],'DESIRED CLASS'!AB19,Table2[CLASS],1) -> 2 | ... AJ20: =COUNTIFS(Table2[WORDS IN CLASS1],'DESIRED CLASS'!AJ19,Table2[CLASS],1) -> 1
I21: likelihood | J21: P(W/C1) | K21: =K20+$W$6/($P$6+$U$6) -> 0.0043290043 | L21: =L20+$W$6/($P$6+$U$6) -> 0.0043290043 | M21: =M20+$W$6/($P$6+$U$6) -> 0.0043290043 | N21: =N20+$W$6/($P$6+$U$6) -> 0.0043290043 | O21: =O20+$W$6/($P$6+$U$6) -> 0.0043290043 | P21: =P20+$W$6/($P$6+$U$6) -> 0.0043290043 | Q21: =Q20+$W$6/($P$6+$U$6) -> 0.0043290043 | R21: =R20+$W$6/($P$6+$U$6) -> 0.0043290043 | ... AJ21: =AJ20+$W$6/($P$6+$U$6) -> 1.004329
J22: P(C1/D9) | K22: =(L6*K21*L21*M21*N21*O21*P21*Q21*R21*S21*T21*U21*V21*W21*X21*Y21*Z21*AB21*AC21*AD21*AE21*AF21*AG21*AH21*AI21*AJ21) -> 1.1689918e-49
J24: P(C0/D10) | K24: layout | L24: hour | M24: little | N24: tricky | O24: print | P24: page | Q24: light | R24: grey | S24: journal | T24: diaper | U24: bottle | V24: med | W24: middle | X24: night | Y24: challenge | Z24: could | AA24: not | AB24: use | AC24: space | AD24: make | AE24: more | AF24: note | AG24: comment | AH24: something | AI24: cute | AJ24: day
K25: =COUNTIFS(Table2[WORDS IN CLASS1],'DESIRED CLASS'!K24,Table2[CLASS],0) -> 0 | L25: =COUNTIFS(Table2[WORDS IN CLASS1],'DESIRED CLASS'!L24,Table2[CLASS],0) -> 0 | M25: =COUNTIFS(Table2[WORDS IN CLASS1],'DESIRED CLASS'!M24,Table2[CLASS],0) -> 0 | N25: =COUNTIFS(Table2[WORDS IN CLASS1],'DESIRED CLASS'!N24,Table2[CLASS],0) -> 0 | O25: =COUNTIFS(Table2[WORDS IN CLASS1],'DESIRED CLASS'!O24,Table2[CLASS],0) -> 0 | P25: =COUNTIFS(Table2[WORDS IN CLASS1],'DESIRED CLASS'!P24,Table2[CLASS],0) -> 0 | Q25: =COUNTIFS(Table2[WORDS IN CLASS1],'DESIRED CLASS'!Q24,Table2[CLASS],0) -> 0 | R25: =COUNTIFS(Table2[WORDS IN CLASS1],'DESIRED CLASS'!R24,Table2[CLASS],0) -> 0 | ... AJ25: =COUNTIFS(Table2[WORDS IN CLASS1],'DESIRED CLASS'!AJ24,Table2[CLASS],0) -> 0
I26: likelihood | J26: P(W/C0) | K26: =K25+$W$6/($P$7+$U$6) -> 0.0068027211 | L26: =L25+$W$6/($P$7+$U$6) -> 0.0068027211 | M26: =M25+$W$6/($P$7+$U$6) -> 0.0068027211 | N26: =N25+$W$6/($P$7+$U$6) -> 0.0068027211 | O26: =O25+$W$6/($P$7+$U$6) -> 0.0068027211 | P26: =P25+$W$6/($P$7+$U$6) -> 0.0068027211 | Q26: =Q25+$W$6/($P$7+$U$6) -> 0.0068027211 | R26: =R25+$W$6/($P$7+$U$6) -> 0.0068027211 | ... AJ26: =AJ25+$W$6/($P$7+$U$6) -> 0.0068027211
J27: P(C0/D10) | K27: =L7*K26*L26*M26*N26*O26*P26*Q26*R26*S26*T26*U26*V26*W26*X26*Y26*Z26*AB26*AC26*AD26*AE26*AF26*AG26*AH26*AI26*AJ26 -> 3.642165e-53
